###错误处理机制
1、Error实例对象
JavaScript 原生提供Error构造函数，所有抛出的错误都是这个构造函数的实例
Error实例对象的属性
```
message：错误提示信息
name：错误名称（非标准属性）
stack：错误的堆栈（非标准属性）
```
2、Error的6个派生对象
2.1、SyntaxError 
SyntaxError对象是解析代码时发生的语法错误

2.2、ReferenceError 对象
ReferenceError对象是引用一个不存在的变量时发生的错误

2.3、RangeError 对象
RangeError对象是一个值超出有效范围时发生的错误

2.4、TypeError 对象
TypeError对象是变量或参数不是预期类型时发生的错误

2.5、URIError 对象
URIError对象是 URI 相关函数的参数不正确时抛出的错误，主要涉及encodeURI()、decodeURI()、encodeURIComponent()、decodeURIComponent()、escape()和unescape()这六个函数

2.6、EvalError 对象
eval函数没有被正确执行时，会抛出EvalError错误

这6种派生错误，连同原始的Error对象，都是构造函数。开发者可以使用它们，手动生成错误对象的实例。这些构造函数都接受一个函数，代表错误提示信息（message）

3、自定义错误
```
function UserError(message) {
  this.message = message || '默认信息';
  this.name = 'UserError';
}

UserError.prototype = new Error();
UserError.prototype.constructor = UserError;
new UserError('这是自定义的错误！');
```

4、throw语句
throw语句的作用是手动中断程序执行，抛出一个错误
throw可以抛出任何类型的值。也就是说，它的参数可以是任何值
```
function UserError(message) {
  this.message = message || '默认信息';
  this.name = 'UserError';
}

throw new UserError('出错了！');
// Uncaught UserError {message: "出错了！", name: "UserError"}
// 抛出一个字符串
throw 'Error！';
// Uncaught Error！

// 抛出一个数值
throw 42;
// Uncaught 42

// 抛出一个布尔值
throw true;
// Uncaught true

// 抛出一个对象
throw {
  toString: function () {
    return 'Error!';
  }
};
// Uncaught {toString: ƒ}
```
5、try...catch
```
try {
  throw new Error('出错了!');
} catch (e) {
  console.log(e.name + ": " + e.message);
  console.log(e.stack);
}
// Error: 出错了!
//   at <anonymous>:3:9
```
try代码块抛出错误（上例用的是throw语句），JavaScript 引擎就立即把代码的执行，转到catch代码块，或者说错误被catch代码块捕获了。catch接受一个参数，表示try代码块抛出的值（try...catch代码还可以嵌套）。

- catch代码块捕获错误之后，程序不会中断，会按照正常流程继续执行下去

```
try {
  throw "出错了";
} catch (e) {
  console.log(111);
}
console.log(222);
// 111
// 222
```
6、finally代码块

try...catch结构允许在最后添加一个finally代码块，表示不管是否出现错误，都必需在最后运行的语句
- 注意try里面有return的情况
```
function idle(x) {
  try {
    console.log(x);
    return 'result';
  } finally {
    console.log("FINALLY");
  }
}
idle('hello')
// hello
// FINALLY
// "result"
```
上面代码说明，try代码块没有发生错误，而且里面还包括return语句，但是finally代码块依然会执行。注意，只有在其执行完毕后，才会显示return语句的值
- 下面的例子说明**return语句的执行是排在finally代码之前，只是等finally代码执行完毕后才返回**
（问题来了：：到底是之前还是之后呢）
```
var count = 0;
function countUp() {
  try {
    return count;
  } finally {
    count++;
  }
}
countUp()
// 0
count
// 1
```
- 充分反映了try...catch...finally这三者之间的执行顺序
catch代码块结束执行之前，会先执行finally代码块
```
function f() {
  try {
    console.log(0);
    throw 'bug';
  } catch(e) {
    console.log(1);
    return true; // 这句原本会延迟到 finally 代码块结束再执行
    console.log(2); // 不会运行
  } finally {
    console.log(3);
    return false; // 这句会覆盖掉前面那句 return
    console.log(4); // 不会运行
  }

  console.log(5); // 不会运行
}
var result = f();
// 0
// 1
// 3
result
```
- 进入catch代码块之后，一遇到throw语句，就会去执行finally代码块，其中有return false语句，因此就直接返回了，不再会回去执行catch代码块剩下的部分了
```
function f() {
  try {
    throw '出错了！';
  } catch(e) {
    console.log('捕捉到内部错误');
    throw e; // 这句原本会等到finally结束再执行
  } finally {
    return false; // 直接返回
  }
}
try {
  f();
} catch(e) {
  // 此处不会执行
  console.log('caught outer "bogus"');
}
//  捕捉到内部错误
```